Building DAG of jobs...
shared_storage_local_copies: True
remote_exec: False
Using shell: /usr/bin/bash
Provided cores: 128
Rules claiming more threads will be scaled down.
Job stats:
job                    count
-------------------  -------
all                        1
get_plot_files_rule        1
total                      2

Resources before job selection: {'_cores': 128, '_nodes': 9223372036854775807}
Ready jobs (1)
Select jobs to execute...
Using greedy selector because only single job has to be scheduled.
Selected jobs (1)
Resources after job selection: {'_cores': 127, '_nodes': 9223372036854775806}
Execute 1 jobs...

[Mon Aug 26 17:07:46 2024]
localrule get_plot_files_rule:
    input: /n/zanderson/SNP-plot-snake/filtered-annotated-VCFs/GM18876-ONT-hg38-R9-LSK110-guppy-sup-5mC.annotated.filtered.bed, /n/zanderson/SNP-plot-snake/filtered-annotated-VCFs/HG02409-ONT-hg38-R9-LSK110-guppy-sup-5mC.annotated.filtered.bed, /n/zanderson/SNP-plot-snake/filtered-annotated-VCFs/HG03861-ONT-hg38-R9-LSK110-guppy-sup-5hmc_5mc_cg.annotated.filtered.bed
    output: /n/zanderson/SNP-plot-snake/filtered-annotated-VCFs/file_list.txt
    jobid: 1
    reason: Missing output files: /n/zanderson/SNP-plot-snake/filtered-annotated-VCFs/file_list.txt
    resources: tmpdir=/tmp

Activating conda environment: iPython-8.15.0
Full Traceback (most recent call last):
  File "/usr/share/millerlab/snakemake-8.16.0/lib/python3.12/site-packages/snakemake/executors/local.py", line 423, in run_wrapper
    run(
  File "/n/zanderson/SNP-plot-snake/workflow/rules/get-plot-files-rule.smk", line 33, in __rule_get_plot_files_rule
  File "/usr/share/millerlab/snakemake-8.16.0/lib/python3.12/site-packages/snakemake/script/__init__.py", line 1563, in script
    executor.evaluate()
  File "/usr/share/millerlab/snakemake-8.16.0/lib/python3.12/site-packages/snakemake/script/__init__.py", line 454, in evaluate
    self.execute_script(fd.name, edit=edit)
  File "/usr/share/millerlab/snakemake-8.16.0/lib/python3.12/site-packages/snakemake/script/__init__.py", line 697, in execute_script
    self._execute_cmd(
  File "/usr/share/millerlab/snakemake-8.16.0/lib/python3.12/site-packages/snakemake/script/__init__.py", line 482, in _execute_cmd
    return shell(
           ^^^^^^
  File "/usr/share/millerlab/snakemake-8.16.0/lib/python3.12/site-packages/snakemake/shell.py", line 357, in __new__
    raise sp.CalledProcessError(retcode, cmd)
subprocess.CalledProcessError: Command 'source /usr/bin/activate 'iPython-8.15.0'; set -euo pipefail;  /usr/share/millerlab/snakemake-8.16.0/bin/python3.12 /n/zanderson/SNP-plot-snake/.snakemake/scripts/tmp_6ecxyyp.get-plot-files.py' returned non-zero exit status 1.

Full Traceback (most recent call last):
  File "/usr/share/millerlab/snakemake-8.16.0/lib/python3.12/site-packages/snakemake/executors/local.py", line 423, in run_wrapper
    run(
  File "/n/zanderson/SNP-plot-snake/workflow/rules/get-plot-files-rule.smk", line 33, in __rule_get_plot_files_rule
  File "/usr/share/millerlab/snakemake-8.16.0/lib/python3.12/site-packages/snakemake/script/__init__.py", line 1563, in script
    executor.evaluate()
  File "/usr/share/millerlab/snakemake-8.16.0/lib/python3.12/site-packages/snakemake/script/__init__.py", line 454, in evaluate
    self.execute_script(fd.name, edit=edit)
  File "/usr/share/millerlab/snakemake-8.16.0/lib/python3.12/site-packages/snakemake/script/__init__.py", line 697, in execute_script
    self._execute_cmd(
  File "/usr/share/millerlab/snakemake-8.16.0/lib/python3.12/site-packages/snakemake/script/__init__.py", line 482, in _execute_cmd
    return shell(
           ^^^^^^
  File "/usr/share/millerlab/snakemake-8.16.0/lib/python3.12/site-packages/snakemake/shell.py", line 357, in __new__
    raise sp.CalledProcessError(retcode, cmd)
subprocess.CalledProcessError: Command 'source /usr/bin/activate 'iPython-8.15.0'; set -euo pipefail;  /usr/share/millerlab/snakemake-8.16.0/bin/python3.12 /n/zanderson/SNP-plot-snake/.snakemake/scripts/tmp_6ecxyyp.get-plot-files.py' returned non-zero exit status 1.

During handling of the above exception, another exception occurred:

Traceback (most recent call last):
  File "/usr/share/millerlab/snakemake-8.16.0/lib/python3.12/site-packages/snakemake/executors/local.py", line 261, in _callback
    raise ex
  File "/usr/share/millerlab/snakemake-8.16.0/lib/python3.12/concurrent/futures/thread.py", line 58, in run
    result = self.fn(*self.args, **self.kwargs)
             ^^^^^^^^^^^^^^^^^^^^^^^^^^^^^^^^^^
  File "/usr/share/millerlab/snakemake-8.16.0/lib/python3.12/site-packages/snakemake/executors/local.py", line 247, in cached_or_run
    run_func(*args)
  File "/usr/share/millerlab/snakemake-8.16.0/lib/python3.12/site-packages/snakemake/executors/local.py", line 459, in run_wrapper
    raise RuleException(
snakemake.exceptions.RuleException: CalledProcessError in file /n/zanderson/SNP-plot-snake/workflow/rules/get-plot-files-rule.smk, line 20:
Command 'source /usr/bin/activate 'iPython-8.15.0'; set -euo pipefail;  /usr/share/millerlab/snakemake-8.16.0/bin/python3.12 /n/zanderson/SNP-plot-snake/.snakemake/scripts/tmp_6ecxyyp.get-plot-files.py' returned non-zero exit status 1.

RuleException:
CalledProcessError in file /n/zanderson/SNP-plot-snake/workflow/rules/get-plot-files-rule.smk, line 20:
Command 'source /usr/bin/activate 'iPython-8.15.0'; set -euo pipefail;  /usr/share/millerlab/snakemake-8.16.0/bin/python3.12 /n/zanderson/SNP-plot-snake/.snakemake/scripts/tmp_6ecxyyp.get-plot-files.py' returned non-zero exit status 1.
[Mon Aug 26 17:07:47 2024]
Error in rule get_plot_files_rule:
    jobid: 1
    input: /n/zanderson/SNP-plot-snake/filtered-annotated-VCFs/GM18876-ONT-hg38-R9-LSK110-guppy-sup-5mC.annotated.filtered.bed, /n/zanderson/SNP-plot-snake/filtered-annotated-VCFs/HG02409-ONT-hg38-R9-LSK110-guppy-sup-5mC.annotated.filtered.bed, /n/zanderson/SNP-plot-snake/filtered-annotated-VCFs/HG03861-ONT-hg38-R9-LSK110-guppy-sup-5hmc_5mc_cg.annotated.filtered.bed
    output: /n/zanderson/SNP-plot-snake/filtered-annotated-VCFs/file_list.txt
    conda-env: iPython-8.15.0

Shutting down, this might take some time.
Exiting because a job execution failed. Look above for error message
Complete log: .snakemake/log/2024-08-26T170744.293685.snakemake.log
unlocking
removing lock
removing lock
removed all locks
Full Traceback (most recent call last):
  File "/usr/share/millerlab/snakemake-8.16.0/lib/python3.12/site-packages/snakemake/cli.py", line 2103, in args_to_api
    dag_api.execute_workflow(
  File "/usr/share/millerlab/snakemake-8.16.0/lib/python3.12/site-packages/snakemake/api.py", line 594, in execute_workflow
    workflow.execute(
  File "/usr/share/millerlab/snakemake-8.16.0/lib/python3.12/site-packages/snakemake/workflow.py", line 1286, in execute
    raise WorkflowError("At least one job did not complete successfully.")
snakemake_interface_common.exceptions.WorkflowError: At least one job did not complete successfully.

WorkflowError:
At least one job did not complete successfully.
